INFO:httpx:HTTP Request: POST https://api.telegram.org/bot6590375844:AAEecUH0x1kspoKxOUy3r82PqACvnRjEs0E/getMe "HTTP/1.1 200 OK"
INFO:httpx:HTTP Request: POST https://api.telegram.org/bot6590375844:AAEecUH0x1kspoKxOUy3r82PqACvnRjEs0E/deleteWebhook "HTTP/1.1 200 OK"
INFO:httpx:HTTP Request: POST https://api.telegram.org/bot6590375844:AAEecUH0x1kspoKxOUy3r82PqACvnRjEs0E/getMe "HTTP/1.1 200 OK"
INFO:httpx:HTTP Request: POST https://api.telegram.org/bot6590375844:AAEecUH0x1kspoKxOUy3r82PqACvnRjEs0E/deleteWebhook "HTTP/1.1 200 OK"
INFO:httpx:HTTP Request: POST https://api.telegram.org/bot6590375844:AAEecUH0x1kspoKxOUy3r82PqACvnRjEs0E/getUpdates "HTTP/1.1 409 Conflict"
ERROR:telegram.ext.Updater:Error while getting Updates: Conflict: terminated by other getUpdates request; make sure that only one bot instance is running
ERROR:telegram.ext.Updater:Exception happened while polling for updates.
Traceback (most recent call last):
  File "/root/name_negar_bot/name_negar_bot/lib/python3.9/site-packages/telegram/ext/_updater.py", line 628, in _network_loop_retry
    if not await action_cb():
  File "/root/name_negar_bot/name_negar_bot/lib/python3.9/site-packages/telegram/ext/_updater.py", line 333, in polling_action_cb
    raise exc
  File "/root/name_negar_bot/name_negar_bot/lib/python3.9/site-packages/telegram/ext/_updater.py", line 322, in polling_action_cb
    updates = await self.bot.get_updates(
  File "/root/name_negar_bot/name_negar_bot/lib/python3.9/site-packages/telegram/_bot.py", line 394, in decorator
    result = await func(self, *args, **kwargs)  # skipcq: PYL-E1102
  File "/root/name_negar_bot/name_negar_bot/lib/python3.9/site-packages/telegram/_bot.py", line 3542, in get_updates
    await self._post(
  File "/root/name_negar_bot/name_negar_bot/lib/python3.9/site-packages/telegram/_bot.py", line 482, in _post
    return await self._do_post(
  File "/root/name_negar_bot/name_negar_bot/lib/python3.9/site-packages/telegram/_bot.py", line 510, in _do_post
    return await request.post(
  File "/root/name_negar_bot/name_negar_bot/lib/python3.9/site-packages/telegram/request/_baserequest.py", line 168, in post
    result = await self._request_wrapper(
  File "/root/name_negar_bot/name_negar_bot/lib/python3.9/site-packages/telegram/request/_baserequest.py", line 327, in _request_wrapper
    raise Conflict(message)
telegram.error.Conflict: Conflict: terminated by other getUpdates request; make sure that only one bot instance is running
INFO:httpx:HTTP Request: POST https://api.telegram.org/bot6590375844:AAEecUH0x1kspoKxOUy3r82PqACvnRjEs0E/getUpdates "HTTP/1.1 200 OK"
INFO:httpx:HTTP Request: POST https://api.telegram.org/bot6590375844:AAEecUH0x1kspoKxOUy3r82PqACvnRjEs0E/getUpdates "HTTP/1.1 409 Conflict"
ERROR:telegram.ext.Updater:Error while getting Updates: Conflict: terminated by other getUpdates request; make sure that only one bot instance is running
ERROR:telegram.ext.Updater:Exception happened while polling for updates.
Traceback (most recent call last):
  File "/root/name_negar_bot/name_negar_bot/lib/python3.9/site-packages/telegram/ext/_updater.py", line 628, in _network_loop_retry
    if not await action_cb():
  File "/root/name_negar_bot/name_negar_bot/lib/python3.9/site-packages/telegram/ext/_updater.py", line 333, in polling_action_cb
    raise exc
  File "/root/name_negar_bot/name_negar_bot/lib/python3.9/site-packages/telegram/ext/_updater.py", line 322, in polling_action_cb
    updates = await self.bot.get_updates(
  File "/root/name_negar_bot/name_negar_bot/lib/python3.9/site-packages/telegram/_bot.py", line 394, in decorator
    result = await func(self, *args, **kwargs)  # skipcq: PYL-E1102
  File "/root/name_negar_bot/name_negar_bot/lib/python3.9/site-packages/telegram/_bot.py", line 3542, in get_updates
    await self._post(
  File "/root/name_negar_bot/name_negar_bot/lib/python3.9/site-packages/telegram/_bot.py", line 482, in _post
    return await self._do_post(
  File "/root/name_negar_bot/name_negar_bot/lib/python3.9/site-packages/telegram/_bot.py", line 510, in _do_post
    return await request.post(
  File "/root/name_negar_bot/name_negar_bot/lib/python3.9/site-packages/telegram/request/_baserequest.py", line 168, in post
    result = await self._request_wrapper(
  File "/root/name_negar_bot/name_negar_bot/lib/python3.9/site-packages/telegram/request/_baserequest.py", line 327, in _request_wrapper
    raise Conflict(message)
telegram.error.Conflict: Conflict: terminated by other getUpdates request; make sure that only one bot instance is running
INFO:httpx:HTTP Request: POST https://api.telegram.org/bot6590375844:AAEecUH0x1kspoKxOUy3r82PqACvnRjEs0E/getUpdates "HTTP/1.1 409 Conflict"
ERROR:telegram.ext.Updater:Error while getting Updates: Conflict: terminated by other getUpdates request; make sure that only one bot instance is running
ERROR:telegram.ext.Updater:Exception happened while polling for updates.
Traceback (most recent call last):
  File "/root/name_negar_bot/name_negar_bot/lib/python3.9/site-packages/telegram/ext/_updater.py", line 628, in _network_loop_retry
    if not await action_cb():
  File "/root/name_negar_bot/name_negar_bot/lib/python3.9/site-packages/telegram/ext/_updater.py", line 333, in polling_action_cb
    raise exc
  File "/root/name_negar_bot/name_negar_bot/lib/python3.9/site-packages/telegram/ext/_updater.py", line 322, in polling_action_cb
    updates = await self.bot.get_updates(
  File "/root/name_negar_bot/name_negar_bot/lib/python3.9/site-packages/telegram/_bot.py", line 394, in decorator
    result = await func(self, *args, **kwargs)  # skipcq: PYL-E1102
  File "/root/name_negar_bot/name_negar_bot/lib/python3.9/site-packages/telegram/_bot.py", line 3542, in get_updates
    await self._post(
  File "/root/name_negar_bot/name_negar_bot/lib/python3.9/site-packages/telegram/_bot.py", line 482, in _post
    return await self._do_post(
  File "/root/name_negar_bot/name_negar_bot/lib/python3.9/site-packages/telegram/_bot.py", line 510, in _do_post
    return await request.post(
  File "/root/name_negar_bot/name_negar_bot/lib/python3.9/site-packages/telegram/request/_baserequest.py", line 168, in post
    result = await self._request_wrapper(
  File "/root/name_negar_bot/name_negar_bot/lib/python3.9/site-packages/telegram/request/_baserequest.py", line 327, in _request_wrapper
    raise Conflict(message)
telegram.error.Conflict: Conflict: terminated by other getUpdates request; make sure that only one bot instance is running
INFO:httpx:HTTP Request: POST https://api.telegram.org/bot6590375844:AAEecUH0x1kspoKxOUy3r82PqACvnRjEs0E/getUpdates "HTTP/1.1 409 Conflict"
ERROR:telegram.ext.Updater:Error while getting Updates: Conflict: terminated by other getUpdates request; make sure that only one bot instance is running
ERROR:telegram.ext.Updater:Exception happened while polling for updates.
Traceback (most recent call last):
  File "/root/name_negar_bot/name_negar_bot/lib/python3.9/site-packages/telegram/ext/_updater.py", line 628, in _network_loop_retry
    if not await action_cb():
  File "/root/name_negar_bot/name_negar_bot/lib/python3.9/site-packages/telegram/ext/_updater.py", line 333, in polling_action_cb
    raise exc
  File "/root/name_negar_bot/name_negar_bot/lib/python3.9/site-packages/telegram/ext/_updater.py", line 322, in polling_action_cb
    updates = await self.bot.get_updates(
  File "/root/name_negar_bot/name_negar_bot/lib/python3.9/site-packages/telegram/_bot.py", line 394, in decorator
    result = await func(self, *args, **kwargs)  # skipcq: PYL-E1102
  File "/root/name_negar_bot/name_negar_bot/lib/python3.9/site-packages/telegram/_bot.py", line 3542, in get_updates
    await self._post(
  File "/root/name_negar_bot/name_negar_bot/lib/python3.9/site-packages/telegram/_bot.py", line 482, in _post
    return await self._do_post(
  File "/root/name_negar_bot/name_negar_bot/lib/python3.9/site-packages/telegram/_bot.py", line 510, in _do_post
    return await request.post(
  File "/root/name_negar_bot/name_negar_bot/lib/python3.9/site-packages/telegram/request/_baserequest.py", line 168, in post
    result = await self._request_wrapper(
  File "/root/name_negar_bot/name_negar_bot/lib/python3.9/site-packages/telegram/request/_baserequest.py", line 327, in _request_wrapper
    raise Conflict(message)
telegram.error.Conflict: Conflict: terminated by other getUpdates request; make sure that only one bot instance is running
INFO:httpx:HTTP Request: POST https://api.telegram.org/bot6590375844:AAEecUH0x1kspoKxOUy3r82PqACvnRjEs0E/getUpdates "HTTP/1.1 409 Conflict"
ERROR:telegram.ext.Updater:Error while getting Updates: Conflict: terminated by other getUpdates request; make sure that only one bot instance is running
ERROR:telegram.ext.Updater:Exception happened while polling for updates.
Traceback (most recent call last):
  File "/root/name_negar_bot/name_negar_bot/lib/python3.9/site-packages/telegram/ext/_updater.py", line 628, in _network_loop_retry
    if not await action_cb():
  File "/root/name_negar_bot/name_negar_bot/lib/python3.9/site-packages/telegram/ext/_updater.py", line 333, in polling_action_cb
    raise exc
  File "/root/name_negar_bot/name_negar_bot/lib/python3.9/site-packages/telegram/ext/_updater.py", line 322, in polling_action_cb
    updates = await self.bot.get_updates(
  File "/root/name_negar_bot/name_negar_bot/lib/python3.9/site-packages/telegram/_bot.py", line 394, in decorator
    result = await func(self, *args, **kwargs)  # skipcq: PYL-E1102
  File "/root/name_negar_bot/name_negar_bot/lib/python3.9/site-packages/telegram/_bot.py", line 3542, in get_updates
    await self._post(
  File "/root/name_negar_bot/name_negar_bot/lib/python3.9/site-packages/telegram/_bot.py", line 482, in _post
    return await self._do_post(
  File "/root/name_negar_bot/name_negar_bot/lib/python3.9/site-packages/telegram/_bot.py", line 510, in _do_post
    return await request.post(
  File "/root/name_negar_bot/name_negar_bot/lib/python3.9/site-packages/telegram/request/_baserequest.py", line 168, in post
    result = await self._request_wrapper(
  File "/root/name_negar_bot/name_negar_bot/lib/python3.9/site-packages/telegram/request/_baserequest.py", line 327, in _request_wrapper
    raise Conflict(message)
telegram.error.Conflict: Conflict: terminated by other getUpdates request; make sure that only one bot instance is running
INFO:httpx:HTTP Request: POST https://api.telegram.org/bot6590375844:AAEecUH0x1kspoKxOUy3r82PqACvnRjEs0E/getUpdates "HTTP/1.1 409 Conflict"
ERROR:telegram.ext.Updater:Error while getting Updates: Conflict: terminated by other getUpdates request; make sure that only one bot instance is running
ERROR:telegram.ext.Updater:Exception happened while polling for updates.
Traceback (most recent call last):
  File "/root/name_negar_bot/name_negar_bot/lib/python3.9/site-packages/telegram/ext/_updater.py", line 628, in _network_loop_retry
    if not await action_cb():
  File "/root/name_negar_bot/name_negar_bot/lib/python3.9/site-packages/telegram/ext/_updater.py", line 333, in polling_action_cb
    raise exc
  File "/root/name_negar_bot/name_negar_bot/lib/python3.9/site-packages/telegram/ext/_updater.py", line 322, in polling_action_cb
    updates = await self.bot.get_updates(
  File "/root/name_negar_bot/name_negar_bot/lib/python3.9/site-packages/telegram/_bot.py", line 394, in decorator
    result = await func(self, *args, **kwargs)  # skipcq: PYL-E1102
  File "/root/name_negar_bot/name_negar_bot/lib/python3.9/site-packages/telegram/_bot.py", line 3542, in get_updates
    await self._post(
  File "/root/name_negar_bot/name_negar_bot/lib/python3.9/site-packages/telegram/_bot.py", line 482, in _post
    return await self._do_post(
  File "/root/name_negar_bot/name_negar_bot/lib/python3.9/site-packages/telegram/_bot.py", line 510, in _do_post
    return await request.post(
  File "/root/name_negar_bot/name_negar_bot/lib/python3.9/site-packages/telegram/request/_baserequest.py", line 168, in post
    result = await self._request_wrapper(
  File "/root/name_negar_bot/name_negar_bot/lib/python3.9/site-packages/telegram/request/_baserequest.py", line 327, in _request_wrapper
    raise Conflict(message)
telegram.error.Conflict: Conflict: terminated by other getUpdates request; make sure that only one bot instance is running
INFO:httpx:HTTP Request: POST https://api.telegram.org/bot6590375844:AAEecUH0x1kspoKxOUy3r82PqACvnRjEs0E/getUpdates "HTTP/1.1 409 Conflict"
ERROR:telegram.ext.Updater:Error while getting Updates: Conflict: terminated by other getUpdates request; make sure that only one bot instance is running
ERROR:telegram.ext.Updater:Exception happened while polling for updates.
Traceback (most recent call last):
  File "/root/name_negar_bot/name_negar_bot/lib/python3.9/site-packages/telegram/ext/_updater.py", line 628, in _network_loop_retry
    if not await action_cb():
  File "/root/name_negar_bot/name_negar_bot/lib/python3.9/site-packages/telegram/ext/_updater.py", line 333, in polling_action_cb
    raise exc
  File "/root/name_negar_bot/name_negar_bot/lib/python3.9/site-packages/telegram/ext/_updater.py", line 322, in polling_action_cb
    updates = await self.bot.get_updates(
  File "/root/name_negar_bot/name_negar_bot/lib/python3.9/site-packages/telegram/_bot.py", line 394, in decorator
    result = await func(self, *args, **kwargs)  # skipcq: PYL-E1102
  File "/root/name_negar_bot/name_negar_bot/lib/python3.9/site-packages/telegram/_bot.py", line 3542, in get_updates
    await self._post(
  File "/root/name_negar_bot/name_negar_bot/lib/python3.9/site-packages/telegram/_bot.py", line 482, in _post
    return await self._do_post(
  File "/root/name_negar_bot/name_negar_bot/lib/python3.9/site-packages/telegram/_bot.py", line 510, in _do_post
    return await request.post(
  File "/root/name_negar_bot/name_negar_bot/lib/python3.9/site-packages/telegram/request/_baserequest.py", line 168, in post
    result = await self._request_wrapper(
  File "/root/name_negar_bot/name_negar_bot/lib/python3.9/site-packages/telegram/request/_baserequest.py", line 327, in _request_wrapper
    raise Conflict(message)
telegram.error.Conflict: Conflict: terminated by other getUpdates request; make sure that only one bot instance is running
INFO:httpx:HTTP Request: POST https://api.telegram.org/bot6590375844:AAEecUH0x1kspoKxOUy3r82PqACvnRjEs0E/getUpdates "HTTP/1.1 200 OK"
INFO:httpx:HTTP Request: POST https://api.telegram.org/bot6590375844:AAEecUH0x1kspoKxOUy3r82PqACvnRjEs0E/getUpdates "HTTP/1.1 409 Conflict"
ERROR:telegram.ext.Updater:Error while getting Updates: Conflict: terminated by other getUpdates request; make sure that only one bot instance is running
ERROR:telegram.ext.Updater:Exception happened while polling for updates.
Traceback (most recent call last):
  File "/root/name_negar_bot/name_negar_bot/lib/python3.9/site-packages/telegram/ext/_updater.py", line 628, in _network_loop_retry
    if not await action_cb():
  File "/root/name_negar_bot/name_negar_bot/lib/python3.9/site-packages/telegram/ext/_updater.py", line 333, in polling_action_cb
    raise exc
  File "/root/name_negar_bot/name_negar_bot/lib/python3.9/site-packages/telegram/ext/_updater.py", line 322, in polling_action_cb
    updates = await self.bot.get_updates(
  File "/root/name_negar_bot/name_negar_bot/lib/python3.9/site-packages/telegram/_bot.py", line 394, in decorator
    result = await func(self, *args, **kwargs)  # skipcq: PYL-E1102
  File "/root/name_negar_bot/name_negar_bot/lib/python3.9/site-packages/telegram/_bot.py", line 3542, in get_updates
    await self._post(
  File "/root/name_negar_bot/name_negar_bot/lib/python3.9/site-packages/telegram/_bot.py", line 482, in _post
    return await self._do_post(
  File "/root/name_negar_bot/name_negar_bot/lib/python3.9/site-packages/telegram/_bot.py", line 510, in _do_post
    return await request.post(
  File "/root/name_negar_bot/name_negar_bot/lib/python3.9/site-packages/telegram/request/_baserequest.py", line 168, in post
    result = await self._request_wrapper(
  File "/root/name_negar_bot/name_negar_bot/lib/python3.9/site-packages/telegram/request/_baserequest.py", line 327, in _request_wrapper
    raise Conflict(message)
telegram.error.Conflict: Conflict: terminated by other getUpdates request; make sure that only one bot instance is running
INFO:httpx:HTTP Request: POST https://api.telegram.org/bot6590375844:AAEecUH0x1kspoKxOUy3r82PqACvnRjEs0E/getMe "HTTP/1.1 200 OK"
INFO:httpx:HTTP Request: POST https://api.telegram.org/bot6590375844:AAEecUH0x1kspoKxOUy3r82PqACvnRjEs0E/getMe "HTTP/1.1 200 OK"
